Some weights of the model checkpoint at bert-base-uncased were not used when initializing BertForSequenceClassification: ['cls.seq_relationship.bias', 'cls.predictions.transform.dense.bias', 'cls.predictions.transform.LayerNorm.weight', 'cls.predictions.bias', 'cls.predictions.transform.LayerNorm.bias', 'cls.predictions.decoder.weight', 'cls.seq_relationship.weight', 'cls.predictions.transform.dense.weight']
- This IS expected if you are initializing BertForSequenceClassification from the checkpoint of a model trained on another task or with another architecture (e.g. initializing a BertForSequenceClassification model from a BertForPreTraining model).
- This IS NOT expected if you are initializing BertForSequenceClassification from the checkpoint of a model that you expect to be exactly identical (initializing a BertForSequenceClassification model from a BertForSequenceClassification model).
Some weights of BertForSequenceClassification were not initialized from the model checkpoint at bert-base-uncased and are newly initialized: ['classifier.weight', 'classifier.bias']
You should probably TRAIN this model on a down-stream task to be able to use it for predictions and inference.
***** Running training *****
  Num examples = 25000
  Num Epochs = 3
  Instantaneous batch size per device = 16
  Total train batch size (w. parallel, distributed & accumulation) = 16
  Gradient Accumulation steps = 1
  Total optimization steps = 4689
Automatic Weights & Biases logging enabled, to disable set os.environ["WANDB_DISABLED"] = "true"
wandb: ERROR api_key not configured (no-tty). call wandb.login(key=[your_api_key])
Traceback (most recent call last):
  File "run_model.py", line 117, in <module>
    trainer.train()
  File "/home/sc.uni-leipzig.de/mh29wade/context-extension/venv/lib64/python3.6/site-packages/transformers/trainer.py", line 1260, in train
    self.control = self.callback_handler.on_train_begin(args, self.state, self.control)
  File "/home/sc.uni-leipzig.de/mh29wade/context-extension/venv/lib64/python3.6/site-packages/transformers/trainer_callback.py", line 346, in on_train_begin
    return self.call_event("on_train_begin", args, state, control)
  File "/home/sc.uni-leipzig.de/mh29wade/context-extension/venv/lib64/python3.6/site-packages/transformers/trainer_callback.py", line 397, in call_event
    **kwargs,
  File "/home/sc.uni-leipzig.de/mh29wade/context-extension/venv/lib64/python3.6/site-packages/transformers/integrations.py", line 540, in on_train_begin
    self.setup(args, state, model, **kwargs)
  File "/home/sc.uni-leipzig.de/mh29wade/context-extension/venv/lib64/python3.6/site-packages/transformers/integrations.py", line 516, in setup
    **init_args,
  File "/home/sc.uni-leipzig.de/mh29wade/context-extension/venv/lib64/python3.6/site-packages/wandb/sdk/wandb_init.py", line 1140, in init
    wi.setup(kwargs)
  File "/home/sc.uni-leipzig.de/mh29wade/context-extension/venv/lib64/python3.6/site-packages/wandb/sdk/wandb_init.py", line 293, in setup
    _entity=kwargs.get("entity") or settings.entity,
  File "/home/sc.uni-leipzig.de/mh29wade/context-extension/venv/lib64/python3.6/site-packages/wandb/sdk/wandb_login.py", line 298, in _login
    wlogin.prompt_api_key()
  File "/home/sc.uni-leipzig.de/mh29wade/context-extension/venv/lib64/python3.6/site-packages/wandb/sdk/wandb_login.py", line 228, in prompt_api_key
    raise UsageError("api_key not configured (no-tty). call " + directive)
wandb.errors.UsageError: api_key not configured (no-tty). call wandb.login(key=[your_api_key])
